Workbook
Name density: #REF!

Sheet Sheet7 (2)
E1: PROFORMA Order（外贸订单 预售发票） | R1: Order Production（内贸订单） | AK1: Prepared（准备好的） | AX1: shipments
A2: No | B2: Incoterms | C2: Data 日期 | D2: INV No 发票号 | E2: SPEC 规格 | F2: INV No 发票号 | G2: Knife No. | H2: Buyer 买家 | I2: SPEC 规格 | J2: QTY 数量 | K2: CNY/ton 单价 | L2: Total 总价 | M2: RECEIVABLE ADV 应收预付款 | N2: Received ADV 已收到预付款 | O2: Balance 尾款 | R2: Supplyer 供应商 | S2: Inv No 发票号（供应商） | T2: Order date 下单日期 | U2: Expect preparation date 预计货好时间 | V2: Actual preparation date 实际货好时间 | W2: Delay date 延迟日期 | X2: Notes 备注 | Y2: QTY 数量 | Z2: CNY/ton 单价 | AA2: Total 总价 | AB2: PAID ADV 已付（供应商） | AC2: Balance 尾款（供应商） | AD2: QTY CASH 数量 现金 | AE2: CNY/ton CASH 单价 现金 | AF2: Total CASH 总价 现金 | AG2: PAID ADV CASH 已付现金（供应商） | AH2: Balance CASH 尾款现金（供应商） | AK2: QTY 数量 | AL2: CNY/ton 单价 | AM2: Total 总价 | AN2: Received ADV 已收到预付款 | AO2: Balance 国外尾款 | AQ2: Actual preparation date 实际货好时间 | AR2: Booking date 订舱时间 | AS2: Notes | AT2: Port | AU2: Booking 预定 | AV2: No containers | AW2: ETD 预计开船日期 | AX2: QTY 出口数量 | AY2: CNY/ton 出口单价 | AZ2: Total 出口总价 | BA2: Received 已收到预付款 | BB2: PAID 国外已付 | BC2: Balance 国外尾款 | BD2: Agents 货代名称 | BE2: Line 船公司 | BF2: ETD 开船时间 | BG2: SEA RATE 海运运费 | BH2: Balance MT | BI2: Status | BL2: TJTW Invoice | BM2: Clent 客户 | BN2: Contract/ Invoice 国外合同号 | BO2: SPEC 规格 | BP2: QTY 数量 | BQ2: Expect preparation date 预计货好时间 | BR2: 应受到
C3: 45580 | D3: INTW-3 | E3: 0.16x782x1033 | F3: INTW-3 | H3: INDX | I3: 0.16x782x1033 | J3: 13 | K3: 6860 | L3: =J3*K3 -> 89180 | M3: =L3*0.3 -> 26754 | N3: 0 | O3: =L3-N3 -> 89180 | R3: CRC | S3: BJHS-XWST-241022-01 | T3: 45589 | U3: =T3+60 -> 45649 | Y3: 16.475 | Z3: 3660 | AA3: =Y3*Z3 -> 60298.5 | AB3: =AA3 -> 60298.5 | AC3: =AA3-AB3 -> 0 | AK3: 12.46 | AL3: 6860 | AM3: =AK3*AL3 -> 85475.6 | AX3: 12.46 | AY3: 8462 | AZ3: =AX3*AY3 -> 105436.52 | BA3: 0 | BB3: 105436.52 | BC3: =AZ3-BB3 -> 0 | BD3: Andy | BE3: XINHELU | BF3: 45653 | BI3: closed | BL3: =D3 -> INTW-3 | BR3: =M3 -> 26754
D4: INTW-3 | S4: обрубки 修边 | AD4: 16.475 | AE4: 30 | AF4: =AD4*AE4 -> 494.25 | AG4: 0 | AH4: =AF4-AG4 -> 494.25 | BR4: =M4 -> 0
D5: INTW-3 | S5: продажа обрубков 卖修边 | Y5: 3.406 | Z5: -3200 | AA5: =Y5*Z5 -> -10899.2 | AB5: =AA5 -> -10899.2 | AC5: =AB5 -> -10899.2 | AD5: 0.033575833 | AE5: -2300 | AF5: =AD5*AE5 -> -77.224415 | BR5: =M5 -> 0
D6: INTW-3 | S6: Логистика 运费 | AD6: 13.125 | AE6: 20 | AF6: =AD6*AE6 -> 262.5 | BR6: =M6 -> 0
D7: INTW-3 | R7: YH | S7: BZJY202411-18 | T7: 45610 | U7: =T7+21 -> 45631 | Y7: 12.695 | Z7: 810 | AA7: =Y7*Z7 -> 10282.95 | BR7: =M7 -> 0
D8: INTW-3 | S8: Логистика 运费 | Y8: 12.695 | Z8: 30 | AA8: =Y8*Z8 -> 380.85 | BR8: =M8 -> 0
D9: INTW-3 | R9: JHL | S9: Олово 镀锡 | Y9: 12.773 | Z9: 1615 | AA9: =Y9*Z9 -> 20628.395 | AB9: 333278.82 | BR9: =M9 -> 0
C10: 45580 | D10: INTW-3 | E10: 0.15x890x866 | F10: INTW-3 | H10: INDX | I10: 0.15x890x866 | J10: 13 | K10: 6950 | L10: =J10*K10 -> 90350 | M10: =L10*0.3 -> 27105 | N10: 0 | O10: =L10-N10 -> 90350 | R10: CRC | S10: BJHS-XWST-241022-01 | T10: 45589 | U10: =T10+60 -> 45649 | Y10: 16.41 | Z10: 3660 | AA10: =Y10*Z10 -> 60060.6 | AB10: =AA10 -> 60060.6 | AC10: =AA10-AB10 -> 0 | AK10: 14.154 | AL10: 6950 | AM10: =AK10*AL10 -> 98370.3 | AX10: 14.154 | AY10: 8552 | AZ10: =AX10*AY10 -> 121045.01 | BA10: 0 | BB10: 121045.01 | BC10: =AZ10-BB10 -> -0.002 | BD10: Andy | BE10: XINHELU | BF10: 45653 | BI10: closed | BR10: =M10 -> 27105
D11: INTW-3 | S11: обрубки 修边 | AD11: 16.41 | AE11: 30 | AF11: =AD11*AE11 -> 492.3 | AG11: 0 | AH11: =AF11-AG11 -> 492.3 | BR11: =M11 -> 0
D12: INTW-3 | S12: продажа обрубков 卖修边 | Y12: 1.596 | Z12: -3200 | AA12: =Y12*Z12 -> -5107.2 | AB12: =AA12 -> -5107.2 | AC12: =AB12 -> -5107.2 | AD12: 0.033443364 | AE12: -2300 | AF12: =AD12*AE12 -> -76.919736 | BR12: =M12 -> 0
D13: INTW-3 | S13: Логистика 运费 | AD13: 14.565 | AE13: 20 | AF13: =AD13*AE13 -> 291.3 | BR13: =M13 -> 0
D14: INTW-3 | R14: YH | S14: BZJY202411-18 | T14: 45610 | U14: =T14+21 -> 45631 | Y14: 13.77 | Z14: 830 | AA14: =Y14*Z14 -> 11429.1 | BR14: =M14 -> 0
D15: INTW-3 | S15: Логистика 运费 | Y15: 17.77 | Z15: 30 | AA15: =Y15*Z15 -> 533.1 | BR15: =M15 -> 0
D16: INTW-3 | R16: JHL | S16: Олово 镀锡 | Y16: 13.906 | Z16: 1695 | AA16: =Y16*Z16 -> 23570.67 | AB16: 333278.82 | BR16: =M16 -> 0
C17: 总数 | D17: INTW-3 | E17: 0.16*782*1033 0.15*890*866 | F17: INTW-3 | H17: INDEX | I17: 0.16*782*1033 0.15*890*866 | J17: =SUM(J3:J16) -> 26 | AA17: =SUM(AA3:AA16) -> 171177.77 | AB17: =AB9+AB16 -> 666557.64 | BI17: closed
D18: NBE-2-3 | E18: 0.23x905x720 T3 2.0/2.0 | F18: NBE-2 | H18: “I.C.E.” LLC | I18: 0.23x905x720 T3 2.0/2.0 | J18: 60 | K18: 7009 | L18: =J18*K18 -> 420540 | M18: =L18*0.3 -> 126162 | N18: =L18*0.3 -> 126162 | O18: =N18-L18 -> -294378 | R18: 海钢云翼 | S18: HY2501015V | T18: 45656 | U18: 45748 | Y18: 63.495 | Z18: 4560 | AA18: =Y18*Z18 -> 289537.2 | AB18: =AA18 -> 289537.2 | AC18: =SUM(AA18:AA19) -> 353621.88 | AK18: =0.588+63.371 -> 63.959 | AL18: 7009 | AM18: =AL18*AK18 -> 448288.63 | AO18: =AM18-AN18 -> 448288.63 | AX18: 63.371 | AY18: 7009 | AZ18: =AY18*AX18 -> 444167.34 | BA18: 239337 | BB18: 298717.96 | BC18: =BB18+BA18-AZ18 -> 93887.621 | BR18: =M18 -> 126162
N19: 298717.96 | S19: Олово 镀锡 | Y19: 64.732 | Z19: 990 | AA19: =Z19*Y19 -> 64084.68 | AB19: =AA19 -> 64084.68 | BR19: =M19 -> 0
S20: Логистика 运费 | BR20: =M20 -> 0
D21: NBE-2-1-905 | E21: 0.23x905x720 T3 1.5/1.5 | F21: NBE-2 | H21: “I.C.E.” LLC | I21: 0.23x905x720 T3 1.5/1.5 | J21: 30 | K21: 6857 | L21: =J21*K21 -> 205710 | M21: =L21*0.3 -> 61713 | N21: =L21*0.3 -> 61713 | O21: =N21-L21 -> -143997 | R21: 海钢云翼 | S21: HY2501015V | T21: 45656 | U21: 45748 | Y21: 31.34 | Z21: 4560 | AA21: =Y21*Z21 -> 142910.4 | AB21: =AA21 -> 142910.4 | AC21: =SUM(AA21:AA22) -> 168132.24 | AK21: =1.112+7.645+20.624 -> 29.381 | AL21: 6857 | AM21: =AL21*AK21 -> 201465.52 | AO21: =AM21-AN21 -> 201465.52 | AX21: 7.645 | AY21: 6857 | AZ21: =AY21*AX21 -> 52421.765 | BA21: 37059.77 | BC21: =BB21+BA21-AZ21 -> -15361.995 | BR21: =M21 -> 61713
D22: NBE-2-2 | N22: 98993.14 | S22: Олово 镀锡 | Y22: 30.026 | Z22: 840 | AA22: =Z22*Y22 -> 25221.84 | AB22: =AA22 -> 25221.84 | AX22: 20.624 | AY22: 6857 | AZ22: =AY22*AX22 -> 141418.77 | BA22: 98993.14 | BC22: =BB22+BA22-AZ22 -> -42425.628 | BR22: =M22 -> 0
S23: Логистика 运费 | BR23: =M23 -> 0
D24: NBE-2-1 | E24: 0.23*850*1040 T3 1.5/1.5 | F24: NBE-2 | H24: “I.C.E.” LLC | I24: 0.23*850*1040 T3 1.5/1.5 | J24: 30 | K24: 5718 | L24: =J24*K24 -> 171540 | M24: =L24*0.3 -> 51462 | N24: =L24*0.3 -> 51462 | O24: =N24-L24 -> -120078 | R24: 海钢云翼 | S24: HY2501015V | T24: 45656 | U24: 45734 | Y24: 25.545 | Z24: 4530 | AA24: =Y24*Z24 -> 115718.85 | AB24: =AA24 -> 115718.85 | AC24: =SUM(AA24:AA25) -> 138789.45 | AK24: 25.634 | AL24: 5718 | AM24: =AL24*AK24 -> 146575.21 | AO24: =AM24-AN24 -> 146575.21 | AX24: 25.634 | AY24: 5718 | AZ24: =AY24*AX24 -> 146575.21 | BA24: 110475.21 | BC24: =BB24+BA24-AZ24 -> -36100.002 | BR24: =M24 -> 51462
S25: Олово 镀锡 | Y25: 25.634 | Z25: 900 | AA25: =Z25*Y25 -> 23070.6 | AB25: =AA25 -> 23070.6 | BR25: =M25 -> 0
S26: Логистика 运费 | BR26: =M26 -> 0
D27: NBE-2-4 | E27: 0.23x905x720 T3 2.0/2.0 | AK27: 0.588 | AL27: 7009 | AM27: =AL27*AK27 -> 4121.292 | AN27: 4121.292 | AO27: =AM27-AN27 -> 0 | AX27: 0.588 | AY27: 7009 | AZ27: =AY27*AX27 -> 4121.292 | BA27: 0 | BR27: =M27 -> 0
E28: 0.23x905x720 T3 1.5/1.5 | AK28: 1.529 | AL28: 6857 | AM28: =AL28*AK28 -> 10484.353 | AN28: 10484.353 | AO28: =AM28-AN28 -> 0 | AX28: 1.529 | AY28: 6857 | AZ28: =AY28*AX28 -> 10484.353 | BA28: 0 | BR28: =M28 -> 0
D29: NBE-2 | E29: 0.23x905x720 T3 2.0/2.0 0.23x905x720 T3 1.5/1.5 0.23*850*1040 T3 1.5/1.5 | L29: =SUM(L18:L28) -> 797790 | N29: =SUM(N18:N28) -> 637048.1 | AA29: =SUM(AA18:AA25) -> 660543.57 | AB29: =SUM(AB18:AB25) -> 660543.57 | AC29: =SUM(AC18:AC24) -> 660543.57 | AN29: =SUM(AN27:AN28) -> 14605.645 | AO29: =SUM(AO27:AO28) -> 0 | AZ29: =SUM(AZ18:AZ28) -> 799188.73 | BA29: =SUM(BA18:BA28) -> 485865.12 | BB29: =SUM(BB18:BB28) -> 298717.96 | BC29: =SUM(BC18:BC28) -> -0.004 | BI29: active
C30: 45729 | D30: INTW-8 | E30: 98.9mm 0.20 #401 SE*2 | H30: INDEX | J30: 1160000 | K30: =157.05/1000 -> 0.15705 | L30: =K30*J30 -> 182178 | M30: =L30*0.3 -> 54653.4 | N30: =54653.4+127524.6 -> 182178 | O30: =L30-N30 -> 0 | R30: ZM | S30: ZM20250403-A1 | T30: 45750 | U30: 45772 | X30: shipped | Y30: 1160000 | Z30: 0.165 | AA30: =Z30*Y30 -> 191400 | AB30: 191400 | AC30: =AA30-AB30 -> 0 | AK30: 1160000 | AL30: =157.05/1000 -> 0.15705 | AM30: =AK30*AL30 -> 182178 | AX30: 1160000 | AY30: =157.05/1000 -> 0.15705 | AZ30: =AX30*AY30 -> 182178 | BR30: =M30 -> 54653.4
C31: 总数 | D31: =D30 -> INTW-8 | E31: =E30 -> 98.9mm 0.20 #401 SE*2 | H31: =H30 -> INDEX | J31: =J30 -> 1160000 | L31: =L30 -> 182178 | X31: shipped | BI31: closed
C32: 45008 | D32: TJTW-1L | E32: 99.8mm 0.21 #401 | F32: TJTW-1L | H32: TW | I32: 99.8mm 0.21 #401 | J32: 923400 | K32: 0.285 | L32: =J32*K32 -> 263169 | R32: ZM | S32: ZM20221229-A11 | T32: 44924 | Y32: 954000 | Z32: 0.285 | AA32: =Y32*Z32 -> 271890 | AK32: 954000 | AL32: 0.257 | AM32: =AK32*AL32 -> 245178 | AX32: 954000 | AY32: 0.257 | AZ32: =AX32*AY32 -> 245178 | BA32: 0 | BC32: =BA32-AZ32 -> -245178 | BR32: =M32 -> 0
R33: 退税 | AA33: =-(AZ32*0.13/1.13) -> -28206.319 | BR33: =M33 -> 0
C34: 45014 | D34: TJTW-1L-2 | E34: 99.8mm 0.21 #401 | F34: TJTW-1L-2 | H34: TW | I34: 99.8mm 0.21 #401 | J34: 923400 | K34: 0.285 | L34: =J34*K34 -> 263169 | R34: ZM | S34: ZM20221229-A11 | Y34: 957600 | Z34: 0.285 | AA34: =Y34*Z34 -> 272916 | AK34: 957600 | AL34: 0.257 | AM34: =AK34*AL34 -> 246103.2 | AX34: 957600 | AY34: 0.257 | AZ34: =AX34*AY34 -> 246103.2 | BA34: 200 | BC34: =BA34-AZ34 -> -245903.2 | BR34: =M34 -> 0
AA35: =-(AZ34*0.13/1.13) -> -28312.758 | BR35: =M35 -> 0
C36: 45022 | D36: TJTW-1L-3 | E36: 99.8mm 0.21 #401 | F36: TJTW-1L-3 | H36: TW | I36: 99.8mm 0.21 #401 | J36: 923400 | K36: 0.285 | L36: =J36*K36 -> 263169 | R36: ZM | S36: ZM20221229-A11 | Y36: 955980 | Z36: 0.285 | AA36: =Y36*Z36 -> 272454.3 | AK36: 955980 | AL36: 0.257 | AM36: =AK36*AL36 -> 245686.86 | AX36: 955980 | AY36: 0.257 | AZ36: =AX36*AY36 -> 245686.86 | BA36: 315602.8 | BC36: =BA36-AZ36 -> 69915.94 | BR36: =M36 -> 0
AA37: =-(AZ36*0.13/1.13) -> -28264.86 | BR37: =M37 -> 0
C38: 45030 | D38: TJTW-1L-4 | E38: 99.8mm 0.21 #401 | F38: TJTW-1L-4 | H38: TW | I38: 99.8mm 0.21 #401 | J38: 923400 | K38: 0.285 | L38: =J38*K38 -> 263169 | R38: ZM | S38: ZM20221229-A11 | Y38: 957600 | Z38: 0.285 | AA38: =Y38*Z38 -> 272916 | AK38: 957600 | AL38: 0.2577 | AM38: =AK38*AL38 -> 246773.52 | AX38: 957600 | AY38: 0.2577 | AZ38: =AX38*AY38 -> 246773.52 | BA38: 246052.1 | BC38: =BA38-AZ38 -> -721.42 | BR38: =M38 -> 0
AA39: =-(AZ38*0.13/1.13) -> -28389.874 | BR39: =M39 -> 0
C40: 45035 | D40: 国外打款 | F40: 国外打款 | BA40: 274770.33 | BC40: =BA40-AZ40 -> 274770.33 | BR40: =M40 -> 0
...

Sheet knife
A1: SKARDA
A2: No. | B2: 直径diam | C2: 厚度thickness | E2: 规格specification | F2: 磨刀费Sharpening fee | H2: Total | I2: TW-67 | J2: TW-70 | K2: TW-76 | L2: TJTW-91 | M2: TJTW-86 | N2: TJTW-90 | O2: TJTW-93 | P2: TJTW-100 | Q2: TJTW-107 | R2: TJTW-124 | S2: TJTW-127 | T2: TJTW-136 | U2: TJTW-137 | V2: TJTW-144
A3: 13 | B3: 96 | C3: 0.18 | D3: 80.3 end | E3: 862*782 | F3: 1493 | G3: * | H3: =SUM(I3:V3) -> 362.939 | J3: 25.585 | K3: 24.956 | N3: 27.566 | O3: 30.576 | P3: 59.371 | R3: 54.18 | S3: 59.705 | U3: 54 | V3: 27
A4: 8 | B4: 107.8 | C4: 0.18 | D4: Twist off | E4: 868*872.4 | F4: 1760 | G4: + | H4: =SUM(I4:V4) -> 1171.068 | I4: 24.544 | J4: 76.278 | K4: 118.963 | M4: 153.728 | N4: 139.77 | O4: 57.168 | P4: 107.273 | Q4: 60.12 | S4: 55.224 | T4: 108 | U4: 135 | V4: 135
A5: 12 | B5: 115.5 | C5: 0.18 | D5: 99 end | E5: 928*934.7 | G5: * | H5: =SUM(I5:V5) -> 167.954 | J5: 32.594 | S5: 27.36 | T5: 27 | U5: 54 | V5: 27
A6: ? | C6: 0.18 | D6: 2pcs can | E6: 936*906.5 | H6: =SUM(I6:V6) -> 54 | J6: 0 | U6: 27 | V6: 27
A7: 7 | B7: 99.8 | C7: 0.16/0.20 | D7: SKO | E7: 892*808.4 | G7: + | H7: =SUM(I7:V7) -> 814.936 | I7: 146.338 | J7: 150.579 | K7: 19.808 | M7: 82.987 | N7: 114.386 | O7: 116.556 | P7: =47.856+27.984 -> 75.84 | Q7: 27.442 | V7: =54+27 -> 81
A8: 11 | B8: 162.8 | C8: 0.18 | D8: 2pcs can | E8: 880*824 | F8: 1493 | G8: * | H8: =SUM(I8:V8) -> 375.095 | J8: 21.729 | R8: 55.79 | S8: 54.576 | T8: 81 | U8: 81 | V8: 81
A9: 10 | B9: 99.54 | C9: 0.18 | D9: 83 end | E9: 890*807.3 | G9: * | H9: =SUM(I9:V9) -> 299.506 | J9: 0 | K9: 37.343 | N9: 30.582 | O9: 26.388 | P9: 48.457 | S9: 48.736 | T9: 54 | U9: 27 | V9: 27
A10: 9 | B10: 90.5 | C10: 0.15 | D10: TO 66mm | E10: 890*917 | H10: =SUM(I10:V10) -> 119.015 | K10: 33.392 | N10: 28.054 | O10: 57.569
A11: TOTAL | H11: =SUM(I11:V11) -> 3127.798 | I11: =SUM(I3:I10) -> 170.882 | J11: =SUM(J3:J10) -> 306.765 | K11: =SUM(K3:K10) -> 234.462 | L11: =SUM(L3:L10) -> 0 | N11: =SUM(N3:N10) -> 340.358 | O11: =SUM(O3:O10) -> 288.257 | P11: =SUM(P3:P10) -> 290.941 | Q11: =SUM(Q3:Q10) -> 87.562 | R11: =SUM(R3:R10) -> 109.97 | S11: =SUM(S3:S10) -> 245.601 | T11: =SUM(T3:T10) -> 270 | U11: =SUM(U3:U10) -> 378 | V11: =SUM(V3:V10) -> 405
A13: OTHERS
A14: No. | B14: 直径diam | C14: 厚度thickness | D14: Customer | E14: 规格specification | H14: Total | I14: 10AN | J14: 15AN | K14: TJTW-64 | L14: 8AN | M14: TJTW-3 | N14: TJTW-13 | O14: 12AN | P14: TJTW-18 | Q14: 20AN | R14: 21AN | S14: 22AN | T14: TJTW-21 | U14: TJTW-38 | V14: TPTW-5 | W14: TJTW-40 | X14: TJTW-33 | Y14: TJTW-49 | Z14: TJTW-50 | AA14: TJTW-55 | AB14: TJTW-61 | AC14: TJTW-999 | AD14: TJTW-74 | AE14: TJTW-85 | AF14: TJTW-75 | AG14: TJTW-80 | AH14: TJTW-125 | AI14: TJTW-115
A15: 1 | B15: 99.8 | C15: 0.15/0.16 | D15: CKO | E15: 820*712 | H15: =SUM(I15:AI15) -> 86.859 | I15: 44.146 | J15: 42.713
A16: 2 | B16: 116.7 | C16: 0.2 | D16: SPEC | E16: 751*710.7 | H16: =SUM(I16:AI16) -> 14.79 | K16: 14.79
A17: 3 | B17: 151 | C17: 0.18 | D17: AMT #2 | E17: 822*764.2 | H17: =SUM(I17:AI17) -> 501.812 | N17: 27.896 | P17: 41.472 | Q17: 52.984 | X17: 41.339 | Y17: 83.654 | AB17: 81.355 | AD17: 122.112 | AF17: 36 | AG17: 15
A18: 5 | B18: 108 | C18: 0.16 | D18: EXIM twist | E18: 775*765 | H18: =SUM(I18:AI18) -> 23.49 | I18: 23.49
A19: 6 | B19: 149 | C19: 0.17 | D19: KML#2 | E19: 818*913 | H19: =SUM(I19:AI19) -> 640.616 | L19: 4.503 | N19: 54.171 | P19: 40.155 | W19: 14.243 | Y19: 13.59 | AA19: 118.484 | AB19: 88.986 | AD19: 134.423 | AF19: 138.284 | AG19: 33.777
A20: 14 | B20: 118 | D20: KLM EOE | E20: 952*959 | H20: =SUM(I20:AI20) -> 0
A21: 15 | B21: 117.5 | C21: 0.2 | D21: SPEC | E21: 963*837.5 | H21: =SUM(I21:AI21) -> 76.054 | AE21: 56.307 | AI21: 19.747
A22: 16 | B22: 160.8 | C22: 0.22 | D22: SPEC | E22: 740*823 | H22: =SUM(I22:AI22) -> 205.875 | AE22: 205.875
A23: 17 | B23: 164.5 | C23: 0.17/0.18 | D23: KML#3 | E23: 905*669.5/836.5 | G23: zhongmin | H23: =SUM(I23:AI23) -> 3622 | L23: 38.81 | M23: 6.711 | N23: 316.478 | O23: 26.906 | P23: 163.523 | Q23: 120.322 | R23: 79.587 | S23: 17.06 | T23: 162.968 | U23: 31.318 | V23: 157.852 | W23: 325.052 | Z23: 368.543 | AB23: 466.824 | AC23: 136.35 | AD23: 522.537 | AF23: 276.964 | AG23: 228.682 | AH23: 175.513
A24: TOTAL | H24: =SUM(I24:AI24) -> 5171.496 | I24: =SUM(I15:I23) -> 67.636 | J24: =SUM(J15:J23) -> 42.713 | K24: =SUM(K15:K23) -> 14.79 | L24: =SUM(L15:L23) -> 43.313 | M24: =SUM(M15:M23) -> 6.711 | N24: =SUM(N15:N23) -> 398.545 | O24: =SUM(O15:O23) -> 26.906 | P24: =SUM(P15:P23) -> 245.15 | ... AI24: =SUM(AI15:AI23) -> 19.747

Sheet payment
A1: 付款的客户 Payer | B1: 发票号 invoice | C1: 规格 specifications | D1: 数量 QTY | E1: 单价 UNT | F1: 总价 TOTAL | G1: 国外已付 paid | H1: 国外未付 Unpaid | I1: 货好时间 Ready date | J1: 状态 Status | K1: 供应商 | O1: LF | P1: 800 | R1: BOC | S1: 752804.58 | U1: VAT | V1: 30446.92 | X1: TRC | Y1: 443.06 | AA1: ABC | AB1: 2756671.4 | AD1: VTB | AE1: 2010 | AG1: 总额 | AH1: =P1+S1+Y1+AB1+AE1 -> 3512729.1
A2: TW | B2: TJTW-9-1 | C2: 99.8mm 0.21 #401 | D2: 957600 | E2: 0.2524 | F2: =E2*D2 -> 241698.24 | G2: =154931.2+86767.04 -> 241698.24 | H2: =F2-G2 -> 0 | I2: 45807 | J2: Shipped | V2: 576408
A3: TW | B3: TJTW-9-2 | C3: 99.8mm 0.21 #401 | D3: 957600 | E3: 0.2524 | F3: =E3*D3 -> 241698.24 | G3: =232698.6+9001.44000000001 -> 241700.04 | H3: =F3-G3+1.8 -> 1.1641577e-11 | I3: 45807 | J3: Shipped
A4: TW | B4: TJTW-11 | C4: #401 ETP BPA FREE | D4: 933520 | E4: 0.244 | F4: =E4*D4 -> 227778.88 | G4: =152976.6+74802.28 -> 227778.88 | H4: =F4-G4 -> 0 | I4: 45807 | J4: Shipped
A5: TW | B5: TJTW-11 | C5: #401 TFS BPA FREE | D5: 478800 | E5: 0.24 | F5: =E5*D5 -> 114912 | G5: 114912 | H5: =F5-G5 -> 0 | I5: 45807 | J5: Shipped
A6: TW | B6: TJTW-11 | C6: #401 TFS | D6: 478800 | E6: 0.235 | F6: =E6*D6 -> 112518 | G6: 112518 | H6: =F6-G6 -> 0 | I6: 45807 | J6: Shipped
A7: TW | B7: TJTW-13 | C7: 0.18*822；0.17*818 | D7: 436.345 | F7: 3603352.9 | G7: =4089971.12-486618.26 -> 3603352.9 | H7: =F7-G7 -> 0 | I7: 45807 | J7: Shipped
A8: TW | B8: TJTW-18 | C8: 0.18*905*836.5 | D8: 374.036 | F8: 2898776.7 | G8: =2842096+458.33+56222.35 -> 2898776.7 | H8: =F8-G8 -> 0 | I8: 45807 | J8: Shipped
A9: TW | B9: TJTW-20 | C9: 99.8mm 0.21 #401 | D9: 2246000 | E9: 0.2344 | F9: =E9*D9 -> 526462.4 | G9: =521173.68+5288.72 -> 526462.4 | H9: =F9-G9 -> 0 | I9: 45807 | J9: Shipped
A10: TW | B10: TJTW-21 | C10: 0.18*905*836.5 | D10: 162.968 | F10: 1225563.1 | G10: =1359750-134186.86 -> 1225563.1 | H10: =F10-G10 -> 0 | I10: 45807 | J10: Shipped
A11: TW | B11: TJTW-23 | C11: 0.16*875*C | D11: 274.657 | E11: 6780 | F11: =E11*D11 -> 1862174.5 | G11: =1124880+737294.46 -> 1862174.5 | H11: =F11-G11 -> 0 | I11: 45807 | J11: Shipped
A12: TW | B12: TJTW-24 | C12: 0.24*963*1026 | D12: 25.164 | E12: 6390 | F12: =E12*D12 -> 160797.96 | G12: =146855.7+313226.43 -> 460082.13 | H12: =SUM(F12:F14)-G12 -> 0 | I12: 45807 | J12: Shipped
A13: TW | B13: TJTW-24 | C13: 0.26*963*1026 | D13: 25.153 | E13: 6330 | F13: =E13*D13 -> 159218.49 | I13: 45807 | J13: Shipped
A14: TW | B14: TJTW-24 | C14: 0.32*856*785 | D14: 22.812 | E14: 6140 | F14: =E14*D14 -> 140065.68 | I14: 45807 | J14: Shipped
A15: TW | B15: TJTW-27 | C15: 99.8mm 0.21 #401 | D15: 2280000 | E15: 0.2329 | F15: =E15*D15 -> 531012 | G15: =510000+21012 -> 531012 | H15: =F15-G15 -> 0 | I15: 45807 | J15: Shipped
A16: TW | B16: TJTW-28 | C16: 0.16*820*C | D16: 343.195 | F16: 1866214.3 | G16: =1000000+866214.275 -> 1866214.3 | H16: =F16-G16 -> 0 | I16: 45807 | J16: Shipped
A17: TW | B17: TJTW-29 | C17: 0.16*820*C | D17: 70.53 | E17: 6841.1 | F17: =E17*D17 -> 482502.78 | G17: =321750+160752.783 -> 482502.78 | H17: =F17-G17 -> 0 | I17: 45807 | J17: Shipped
A18: TW | B18: TJTW-30 | C18: 0.22*903*836.5 | D18: 744 | E18: 26.305 | F18: =E18*D18 -> 19570.92 | G18: =26147.17 -> 26147.17 | H18: =SUM(F18:F19)-G18 -> 0 | I18: 45807 | J18: Shipped
A19: TW | B19: TJTW-30 | C19: 0.22*295 | D19: 250 | E19: 26.305 | F19: =E19*D19 -> 6576.25 | I19: 45807 | J19: Shipped
A20: TW | B20: TJTW-31 | C20: 0.16*820*Coil | D20: 156.698 | E20: 6320 | F20: =E20*D20 -> 990331.36 | G20: =980000+10331.3600000001 -> 990331.36 | H20: =F20-G20 -> 0 | I20: 45807 | J20: Shipped
A21: TW | B21: TJTW-33 | C21: 0.18*822*764.2 | D21: 41.339 | E21: 6350 | F21: =E21*D21 -> 262502.65 | G21: =99000+63216.31+100286.34 -> 262502.65 | H21: =F21-G21 -> 0 | I21: 45807 | J21: Shipped
A22: TW | B22: TJTW-34 | C22: 99.8mm 0.21 #401 | D22: 2275275 | E22: 0.2334 | F22: =E22*D22 -> 531049.19 | G22: =500000+31049.185 -> 531049.19 | H22: =F22-G22 -> 0 | I22: 45807 | J22: Shipped
A23: TW | B23: TJTW-35 | C23: 0.16X875xC | D23: 264.507 | E23: 6160 | F23: =E23*D23 -> 1629363.1 | G23: =1688400-59036.8799999999 -> 1629363.1 | H23: =F23-G23 -> 0 | I23: 45807 | J23: Shipped
A24: TW | B24: TJTW-37 | C24: 0.21x894x1038 | D24: 42.337 | E24: 5892 | F24: =E24*D24 -> 249449.6 | G24: =547057-17480.4519999999 -> 529576.55 | H24: =SUM(F24:F25)-G24 -> 0 | I24: 45807 | J24: Shipped
A25: TW | B25: TJTW-37 | C25: 0.16x960x924 | D25: 44.592 | E25: 6282 | F25: =E25*D25 -> 280126.94 | I25: 45807 | J25: Shipped
A26: TW | B26: TJTW-40 | C26: 0.18*905*836.5 | D26: 339.295 | F26: 2337593.4 | G26: =2875989-538395.65 -> 2337593.4 | H26: =F26-G26 -> 0 | I26: 45807 | J26: Shipped
A27: TW | B27: TJTW-41 | C27: #401 | D27: 2280000 | E27: 0.2329 | F27: =E27*D27 -> 531012 | G27: =701780-170768 -> 531012 | H27: =F27-G27 -> 0 | I27: 45807 | J27: Shipped
A28: TW | B28: TJTW-44 | C28: 99.8mm 0.21 #401 | D28: 2097600 | E28: 0.23 | F28: =E28*D28 -> 482448 | G28: =499960-17512 -> 482448 | H28: =F28-G28 -> 0 | I28: 45807 | J28: Shipped
A29: TW | B29: TJTW-47 | C29: EOE ALU 0.24 #401 | D29: 934800 | E29: 0.367 | F29: =E29*D29 -> 343071.6 | G29: =120000+247000-23928.4 -> 343071.6 | H29: =F29-G29 -> 0 | I29: 45971
A30: TW | B30: TJTW-49 | C30: 0.18*822*764.2 2.8/2.8 T4 stone,BA | D30: 83.654 | E30: 6650 | F30: =E30*D30 -> 556299.1 | G30: =661150-11759.4 -> 649390.6 | H30: =SUM(F30:F31)-G30 -> 0 | I30: 45807 | J30: Shipped
A31: TW | B31: TJTW-49 | C31: 0.17*818*913.6 2.8/2.8 T4 stone,BA | D31: 13.59 | E31: 6850 | F31: =E31*D31 -> 93091.5 | I31: 45807 | J31: Shipped
A32: TW | B32: TJTW-50-1 | C32: 0.18*905*669.5 素铁 | D32: 136.35 | E32: 6570 | F32: =E32*D32 -> 895819.5 | G32: =2334554.25+134259.95 -> 2468814.2 | H32: =(SUM(F32:F38))-G32 -> 0 | I32: 45807 | J32: Shipped
A33: TW | B33: TJTW-50-2 | C33: 0.18*905*669.5 素铁 | D33: 7.575 | E33: 6640 | F33: =E33*D33 -> 50298 | I33: 45807 | J33: Shipped
A34: TW | B34: TJTW-50-2 | C34: 0.18*905*836.5 铝膏+黄 BPA free | D34: 54.339 | E34: 6640 | F34: =E34*D34 -> 360810.96 | I34: 45807 | J34: Shipped
A35: TW | B35: TJTW-50-2 | C35: 0.17*905*836.5 铝膏+有机 BPA free | D35: 43.501 | E35: 6790 | F35: =E35*D35 -> 295371.79 | I35: 45807 | J35: Shipped
A36: TW | B36: TJTW-50-3 | C36: 0.17*905*836.5 铝膏+有机 BPA free | D36: 54.54 | E36: 6790 | F36: =E36*D36 -> 370326.6 | I36: 45807 | J36: Shipped
A37: TW | B37: TJTW-50-4 | C37: 0.17*905*836.5 铝膏+有机 BPA free | D37: 9.047 | E37: 7000 | F37: =E37*D37 -> 63329 | I37: 45807 | J37: Shipped
A38: TW | B38: TJTW-50-4 | C38: 0.18*905*836.5 铝膏+有机 BPA free | D38: 63.191 | E38: 6850 | F38: =E38*D38 -> 432858.35 | I38: 45807 | J38: Shipped
A39: TW | B39: TJTW-51 | C39: 0,16x784x1040 2.0/2.0 | D39: 13.806 | E39: 6330 | F39: =E39*D39 -> 87391.98 | G39: 87391.98 | H39: =F39-G39 -> 0 | I39: 45807 | J39: Shipped
A40: TW | B40: TJTW-53 | C40: ETP EOE 99 BPA FREE | D40: 2097600 | E40: 0.23 | F40: =E40*D40 -> 482448 | G40: =476364.96+6083.04 -> 482448 | H40: =F40-G40 -> 0 | I40: 45807 | J40: Shipped
...

Sheet Varnish
A1: PROFORMA Order（外贸订单 预售发票） | R1: Order Production（内贸订单） | AH1: Prepared（准备好的） | AN1: shipments
A2: No | B2: Data 日期 | C2: INV No 发票号 | D2: SPEC 规格 | E2: INV No 发票号 | G2: Preparation date 货好日期 | H2: Buyer 买家 | I2: SPEC 规格 | J2: QTY 数量 | K2: CNY/ton 单价 | L2: Total 总价 | M2: RECEIVABLE ADV 应收预付款 | N2: Received ADV 已收到预付款 | O2: Balance 尾款 | R2: Supplyer 供应商 | S2: Inv No 发票号（供应商） | T2: Order date 下单日期 | U2: Preparation date 货好时间 | V2: QTY 数量 | W2: CNY/ton 单价 | X2: Total 总价 | Y2: PAID ADV 已付（供应商） | Z2: Balance 尾款（供应商） | AA2: QTY CASH 数量 现金 | AB2: CNY/ton CASH 单价 现金 | AC2: Total CASH 总价 现金 | AD2: PAID ADV CASH 已付现金（供应商） | AE2: Balance CASH 尾款现金（供应商） | AH2: QTY 数量 | AI2: CNY/ton 单价 | AJ2: Total 总价 | AK2: Received ADV 已收到预付款 | AL2: Balance 国外尾款 | AN2: QTY 出口数量 | AO2: CNY/ton 出口单价 | AP2: Total 出口总价 | AQ2: Received 已收到预付款 | AR2: PAID 国外已付 | AS2: Balance 国外尾款 | AT2: Agents 货代名称 | AU2: Line 船公司 | AV2: ETD 开船时间 | AW2: SEA RATE 海运运费 | AX2: Balance MT | AY2: Status
B3: 45215 | C3: TJTW-8-1 | D3: 0.18*905*669.5 | E3: TJTW-8-1 | H3: TW | I3: 0.18*905*669.5 | J3: 81 | K3: 6950 | L3: =J3*K3 -> 562950 | R3: ZM | V3: 81.81 | W3: 6750 | X3: =V3*W3 -> 552217.5 | AH3: 81.81 | AI3: 6950 | AJ3: =AI3*AH3 -> 568579.5 | AN3: 81.81 | AO3: 6950 | AP3: =AO3*AN3 -> 568579.5 | AQ3: 0 | AS3: =AQ3-AP3 -> -568579.5
B4: 45215 | C4: TJTW-8-2 | D4: 0.18*905*669.5 | E4: TJTW-8-2 | H4: TW | I4: 0.18*905*669.5 | J4: 81 | K4: 6950 | L4: =J4*K4 -> 562950 | R4: ZM | V4: 82.298 | W4: 6750 | X4: =V4*W4 -> 555511.5 | AH4: 82.298 | AI4: 6950 | AJ4: =AI4*AH4 -> 571971.1 | AN4: 82.298 | AO4: 6950 | AP4: =AO4*AN4 -> 571971.1 | AQ4: 607500 | AS4: =AQ4-AP4 -> 35528.9
B5: 45215 | C5: TJTW-8-3 | D5: 0.18*905*836.5 | E5: TJTW-8-3 | H5: TW | I5: 0.18*905*836.5 | J5: 81 | K5: 9375 | L5: =J5*K5 -> 759375 | R5: ZM | V5: 81.651 | W5: 9150 | X5: =V5*W5 -> 747106.65 | AH5: 81.651 | AI5: 9375 | AJ5: =AI5*AH5 -> 765478.12 | AN5: 81.651 | AO5: 9375 | AP5: =AO5*AN5 -> 765478.12 | AQ5: 59489.84 | AS5: =AQ5-AP5 -> -705988.29
B6: 45215 | C6: TJTW-8-4 | D6: 0.18*905*836.5 | E6: TJTW-8-4 | H6: TW | I6: 0.18*905*836.5 | J6: 81 | K6: 9375 | L6: =J6*K6 -> 759375 | R6: ZM | V6: 81.473 | W6: 9150 | X6: =V6*W6 -> 745477.95 | AH6: 81.473 | AI6: 9375 | AJ6: =AI6*AH6 -> 763809.38 | AN6: 81.473 | AO6: 9375 | AP6: =AO6*AN6 -> 763809.38 | AQ6: 1800000 | AS6: =AQ6-AP6 -> 1036190.6
B7: 45216 | C7: 国外打款 | E7: 国外打款 | H7: TW | AQ7: 202848.26 | AS7: =AQ7-AP7 -> 202848.26
B8: 45212 | C8: TJTW-11 | D8: #401 ETP BPA FREE | E8: TJTW-11 | H8: TW | I8: #401 ETP BPA FREE | J8: 933520 | K8: 0.27 | L8: =J8*K8 -> 252050.4 | R8: ZM | V8: 933520 | W8: 0.27 | X8: =V8*W8 -> 252050.4 | AH8: 933520 | AI8: 0.244 | AJ8: =AH8*AI8 -> 227778.88 | AN8: 933520 | AO8: 0.244 | AP8: =AN8*AO8 -> 227778.88 | AQ8: 152976.6 | AS8: =AQ8-AP8 -> -74802.28
D9: #401 TFS BPA FREE | I9: #401 TFS BPA FREE | J9: 478800 | K9: 0.265 | L9: =J9*K9 -> 126882 | R9: ZM | V9: 478800 | W9: 0.265 | X9: =V9*W9 -> 126882 | AH9: 478800 | AI9: 0.24 | AJ9: =AH9*AI9 -> 114912 | AN9: 478800 | AO9: 0.24 | AP9: =AN9*AO9 -> 114912 | AS9: =AQ9-AP9 -> -114912
D10: #401 TFS | I10: #401 TFS | J10: 478800 | K10: 0.26 | L10: =J10*K10 -> 124488 | R10: ZM | V10: 478800 | W10: 0.26 | X10: =V10*W10 -> 124488 | AH10: 478800 | AI10: 0.235 | AJ10: =AH10*AI10 -> 112518 | AN10: 478800 | AO10: 0.235 | AP10: =AN10*AO10 -> 112518 | AS10: =AQ10-AP10 -> -112518
B11: 45440 | C11: TJTW-22 | D11: 72.9 mm 0.19#300 | E11: TJTW-22 | H11: TW | I11: 72.9 mm 0.19#300 | J11: 1956050 | K11: 0.01832 | L11: =J11*K11 -> 35834.836 | R11: ZM | V11: 1956050 | W11: 0.137 | X11: =V11*W11 -> 267978.85 | AH11: 1956050 | AI11: 0.01832 | AJ11: =AH11*AI11 -> 35834.836 | AN11: 1956050 | AO11: 0.01832 | AP11: =AN11*AO11 -> 35834.836 | AQ11: 7114.8 | AS11: =AQ11-AP11 -> -28720.036
H12: TW | AQ12: 28559.58 | AS12: =AQ12-AP12 -> 28559.58
B13: 45544 | C13: TJTW-33 | D13: 0.18*822*764.2 | E13: TJTW-33 | H13: TW | I13: 0.18*822*764.2 | J13: 54 | K13: 6280 | L13: =J13*K13 -> 339120 | N13: 99000 | O13: =L13-N13 -> 240120 | R13: ZM | S13: ZM20240918-A1 | T13: 45553 | U13: =T13+60 -> 45613 | V13: 50 | W13: 6100 | X13: =V13*W13 -> 305000 | AQ13: 99000 | AS13: =AR13+AQ13-AP13 -> 99000
C14: TJTW-33-1 | E14: TJTW-33-1 | H14: TW | AH14: 41.339 | AI14: 6350 | AJ14: =AH14*AI14 -> 262502.65 | AN14: 41.339 | AO14: 6350 | AP14: =AN14*AO14 -> 262502.65 | AS14: =AR14+AQ14-AP14 -> -262502.65
B15: 45546 | C15: TJTW-35 | D15: 0.16X875xC | E15: TJTW-35 | G15: =B15+60 -> 45606 | H15: TW | I15: 0.16X875xC | J15: 270 | K15: 6160 | L15: =J15*K15 -> 1663200 | N15: 608400 | O15: =L15-N15 -> 1054800 | R15: CRC | S15: BJHS-XWST-241022-01 | T15: 45587 | U15: =T15+60 -> 45647 | V15: 312.365 | W15: 3660 | X15: =V15*W15 -> 1143255.9 | Y15: 1143255.9 | Z15: =X15-Y15 -> 0 | AH15: 264.507 | AI15: 6160 | AJ15: =AH15*AI15 -> 1629363.1 | AN15: =AH15 -> 264.507 | AO15: 6160 | AP15: =AN15*AO15 -> 1629363.1 | AQ15: =N15 -> 608400 | AR15: 1080000 | AS15: =AR15+AQ15-AP15 -> 59036.88 | AT15: ANDY | AU15: EMC | AV15: 45635 | AW15: 2800 | AX15: =AH15-AN15 -> 0 | AY15: closed
S16: обрубки 修边 | AA16: 312.365 | AB16: 30 | AC16: =AA16*AB16 -> 9370.95 | AD16: 0 | AE16: =AC16-AD16 -> 9370.95 | AY16: closed
S17: продажа обрубков 卖修边 | V17: 35.258 | W17: -3200 | X17: =V17*W17 -> -112825.6 | Y17: =X17 -> -112825.6 | Z17: =Y17 -> -112825.6 | AA17: 0.63659575 | AB17: -2300 | AC17: =AA17*AB17 -> -1464.1702 | AY17: closed
S18: Логистика 运费 | AA18: 275.84 | AB18: 20 | AC18: =AA18*AB18 -> 5516.8 | AY18: closed
R19: YH | S19: BZJY202411-18 | T19: 45610 | U19: =T19+21 -> 45631 | V19: 263.883 | W19: 810 | X19: =V19*W19 -> 213745.23 | Y19: 213745.23 | Z19: =X19-Y19 -> 0 | AY19: closed
S20: Логистика 运费 | V20: 263.883 | W20: 30 | X20: =V20*W20 -> 7916.49 | Z20: =X20-Y20 -> 7916.49 | AY20: closed
R21: JHL | S21: Олово 镀锡 | T21: 45627 | U21: 45627 | V21: 264.507 | W21: 1260 | X21: =V21*W21 -> 333278.82 | Y21: 333278.82 | Z21: =X21-Y21 -> 0 | AY21: closed
AY22: closed
B23: 45560 | C23: TJTW-37 | D23: 0.21x894x1038 | E23: TJTW-37 | G23: =B23+60 -> 45620 | H23: TW | I23: 0.21x894x1038 | J23: 48 | K23: 6490 | L23: =J23*K23 -> 311520 | N23: =159057/2+388000/2 -> 273528.5 | O23: =L23-N23 -> 37991.5 | R23: CRC | S23: BJHS-XWST-241022-01 | T23: 45589 | U23: =T23+60 -> 45649 | V23: 49.09 | W23: 3660 | X23: =V23*W23 -> 179669.4 | Y23: =X23 -> 179669.4 | Z23: =X23-Y23 -> 0 | AH23: 42.337 | AI23: 5892 | AJ23: =AI23*AH23 -> 249449.6 | AK23: =N23 -> 273528.5 | AL23: =AJ23-AK23 -> -24078.896 | AN23: 42.503 | AO23: 5892 | AP23: =AO23*AN23 -> 250427.68 | AR23: 388000 | AS23: =AQ23+AR23-AP23 -> 137572.32
S24: обрубки 修边 | AA24: 49.09 | AB24: 30 | AC24: =AA24*AB24 -> 1472.7 | AD24: 0 | AE24: =AC24-AD24 -> 1472.7
S25: продажа обрубков 卖修边 | V25: 4.68 | W25: -3200 | X25: =V25*W25 -> -14976 | Y25: =X25 -> -14976 | Z25: =Y25 -> -14976 | AA25: 0.10004477 | AB25: -2300 | AC25: =AA25*AB25 -> -230.10298
S26: Логистика 运费 | AA26: 44.68 | AB26: 20 | AC26: =AA26*AB26 -> 893.6
R27: YH | S27: BZJY202411-18 | T27: 45610 | U27: =T27+21 -> 45631 | V27: 42.214 | W27: 650 | X27: =V27*W27 -> 27439.1 | Z27: =X27-Y27 -> 27439.1
S28: Логистика 运费 | V28: 42.214 | W28: 30 | X28: =V28*W28 -> 1266.42 | Z28: =X28-Y28 -> 1266.42
R29: JHL | S29: Олово 镀锡 | T29: 45627 | U29: 45627 | V29: 42.337 | W29: 1035 | X29: =V29*W29 -> 43818.795 | Z29: =X29-Y29 -> 43818.795
B30: 45560 | C30: TJTW-37 | D30: 0.16x960x924 | E30: TJTW-37 | G30: =B30+60 -> 45620 | H30: TW | I30: 0.16x960x924 | J30: 48 | K30: 6980 | L30: =J30*K30 -> 335040 | N30: =159057/2+388000/2 -> 273528.5 | O30: =L30-N30 -> 61511.5 | R30: CRC | S30: BJHS-XWST-241022-01 | T30: 45589 | U30: =T30+60 -> 45649 | V30: 49.235 | W30: 3660 | X30: =V30*W30 -> 180200.1 | Y30: =X30 -> 180200.1 | Z30: =X30-Y30 -> 0 | AH30: 44.592 | AI30: 6282 | AJ30: =AI30*AH30 -> 280126.94 | AK30: =N30 -> 273528.5 | AL30: =AJ30-AK30 -> 6598.444 | AN30: 45.198 | AO30: 6282 | AP30: =AO30*AN30 -> 283933.84 | AR30: 159057 | AS30: =AQ30+AR30-AP30 -> -124876.84
S31: обрубки 修边 | AA31: 49.235 | AB31: 30 | AC31: =AA31*AB31 -> 1477.05 | AD31: 0 | AE31: =AC31-AD31 -> 1477.05
S32: продажа обрубков 卖修边 | V32: 1.432 | W32: -3200 | X32: =V32*W32 -> -4582.4 | Y32: =X32 -> -4582.4 | Z32: =Y32 -> -4582.4 | AA32: 0.10034028 | AB32: -2300 | AC32: =AA32*AB32 -> -230.78265
S33: Логистика 运费 | AA33: 47.905 | AB33: 20 | AC33: =AA33*AB33 -> 958.1
R34: YH | S34: BZJY202411-18 | T34: 45610 | U34: =T34+21 -> 45631 | V34: 44.821 | W34: 810 | X34: =V34*W34 -> 36305.01 | Z34: =X34-Y34 -> 36305.01
S35: Логистика 运费 | V35: 44.821 | W35: 30 | X35: =V35*W35 -> 1344.63 | Z35: =X35-Y35 -> 1344.63
N36: =SUM(N23:N35) -> 547057 | O36: =SUM(O23:O35) -> 99503 | R36: JHL | S36: Олово 镀锡 | V36: 44.592 | W36: 1270 | X36: =V36*W36 -> 56631.84 | Z36: =X36-Y36 -> 56631.84 | AH36: =SUM(AH23:AH35) -> 86.929 | AJ36: =SUM(AJ23:AJ35) -> 529576.55
B37: 45587 | C37: PI TJTW-40 | D37: 0.18*905*836.5 | E37: TJTW-40 | G37: =B37+60 -> 45647 | H37: TW | I37: 0.18*905*836.5 | J37: 150 | K37: 9350 | L37: =J37*K37 -> 1402500 | N37: 300000 | O37: =L37-N37 -> 1102500 | R37: ZM | S37: ZM20241022-A1 | T37: 45587 | U37: =T37+60 -> 45647 | V37: 150 | W37: 9350 | X37: =V37*W37 -> 1402500 | AQ37: 566000 | AS37: =AQ37-AP37 -> 566000
B38: 45674 | C38: CI TJTW-40-1 | D38: 0.18*905*836.5 | E38: TJTW-40-1 | H38: TW | I38: 0.18*905*836.5 | R38: ZM | V38: 54.57 | W38: 6600 | X38: =V38*W38 -> 360162 | AH38: 54.57 | AI38: 6850 | AJ38: =AH38*AI38 -> 373804.5 | AK38: =566000/336.253*AH38 -> 91855.299 | AL38: =AK38-AJ38 -> -281949.2 | AN38: 54.57 | AO38: 6850 | AP38: =AN38*AO38 -> 373804.5 | AS38: =AQ38-AP38 -> -373804.5
B39: 45677 | C39: CI TJTW-40-2 | D39: 0.18*905*669.5 | E39: TJTW-40-2 | H39: TW | I39: 0.18*905*669.5 | R39: ZM | V39: 19.695 | W39: 6600 | X39: =V39*W39 -> 129987 | AH39: 19.695 | AI39: 6850 | AJ39: =AH39*AI39 -> 134910.75 | AK39: =566000/336.253*AH39 -> 33151.734 | AL39: =AK39-AJ39 -> -101759.02 | AN39: 19.695 | AO39: 6850 | AP39: =AN39*AO39 -> 134910.75 | AS39: =AQ39-AP39 -> -134910.75
B40: 45677 | C40: CI TJTW-40-2 | D40: 0.18*905*836.5 | H40: TW | R40: ZM | V40: 8.025 | W40: 6600 | X40: =V40*W40 -> 52965 | AH40: 8.025 | AI40: 6850 | AJ40: =AH40*AI40 -> 54971.25 | AK40: =566000/336.253*AH40 -> 13508.132 | AL40: =AK40-AJ40 -> -41463.118 | AN40: 8.025 | AO40: 6850 | AP40: =AN40*AO40 -> 54971.25 | AS40: =AQ40-AP40 -> -54971.25
...

Sheet payment1
C1: Total | E1: TW | F1: BD | G1: NBE | H1: PT | I1: INDKS | J1: NF USD | K1: NF CNY 7,1 | L1: Client payments | M1: Balance
B2: Before | C2: =SUMIFS(payment!H2:H1436,payment!I2:I1436,">="&DATE(2024,6,1),payment!I2:I1436,"<="&DATE(2025,5,31)) -> 1.1641577e-11 | E2: =SUMIFS(payment!H2:H1436,payment!I2:I1436,">="&DATE(2024,6,1),payment!I2:I1436,"<="&DATE(2025,5,31),payment!A2:A1436,"=TW") -> 1.1641577e-11 | F2: 496767.44 | G2: =SUMIFS(payment!H2:H1436,payment!I2:I1436,">="&DATE(2024,6,1),payment!I2:I1436,"<="&DATE(2025,5,31),payment!A2:A1436,"=NBE") -> 0 | H2: =SUMIFS(payment!H2:H1436,payment!I2:I1436,">="&DATE(2024,6,1),payment!I2:I1436,"<="&DATE(2025,5,31),payment!A2:A1436,"=PT") -> 0 | I2: =SUMIFS(payment!H2:H1436,payment!I2:I1436,">="&DATE(2024,6,1),payment!I2:I1436,"<="&DATE(2025,5,31),payment!A2:A1436,"=IN") -> 0 | J2: =SUMIFS(payment!H2:H1436,payment!I2:I1436,">="&DATE(2024,6,1),payment!I2:I1436,"<="&DATE(2025,5,31),payment!A2:A1436,"=NF") -> 0 | K2: =J2*7.1 -> 0 | L2: =SUMIFS(payment!H2:H1436,payment!L2:L1436,">="&DATE(2024,6,1),payment!L2:L1436,"<="&DATE(2025,5,31)) -> 0 | M2: =payment!AH$1-C2+L2 -> 3512729.1
B3: June 1-7 | C3: =SUMIFS(payment!H2:H1436,payment!I2:I1436,">="&DATE(2025,6,1),payment!I2:I1436,"<="&DATE(2025,6,7)) -> 0 | E3: =SUMIFS(payment!H2:H1436,payment!I2:I1436,">="&DATE(2025,6,1),payment!I2:I1436,"<="&DATE(2025,6,7),payment!A2:A1436,"=TW") -> 0 | F3: =SUMIFS(payment!H2:H1436,payment!I2:I1436,">="&DATE(2025,6,1),payment!I2:I1436,"<="&DATE(2025,6,7),payment!A2:A1436,"=VARNISHED") -> 0 | G3: =SUMIFS(payment!H2:H1436,payment!I2:I1436,">="&DATE(2025,6,1),payment!I2:I1436,"<="&DATE(2025,6,7),payment!A2:A1436,"=NBE") -> 0 | H3: =SUMIFS(payment!H2:H1436,payment!I2:I1436,">="&DATE(2025,6,1),payment!I2:I1436,"<="&DATE(2025,6,7),payment!A2:A1436,"=PT") -> 0 | I3: =SUMIFS(payment!H2:H1436,payment!I2:I1436,">="&DATE(2025,6,1),payment!I2:I1436,"<="&DATE(2025,6,7),payment!A2:A1436,"=IN") -> 0 | J3: =SUMIFS(payment!H2:H1436,payment!I2:I1436,">="&DATE(2025,6,1),payment!I2:I1436,"<="&DATE(2025,6,7),payment!A2:A1436,"=NF") -> 0 | K3: =J3*7.1 -> 0 | L3: =SUMIFS(payment!H2:H1436,payment!L2:L1436,">="&DATE(2025,6,1),payment!L2:L1436,"<="&DATE(2025,6,7)) -> 0 | M3: =M2-C3+L3 -> 3512729.1
B4: June 8-15 | C4: =SUMIFS(payment!H2:H1436,payment!I2:I1436,">="&DATE(2025,6,8),payment!I2:I1436,"<="&DATE(2025,6,15)) -> 0 | E4: =SUMIFS(payment!H2:H1436,payment!I2:I1436,">="&DATE(2025,6,8),payment!I2:I1436,"<="&DATE(2025,6,15),payment!A2:A1436,"=TW") -> 0 | F4: =SUMIFS(payment!H2:H1436,payment!I2:I1436,">="&DATE(2025,6,8),payment!I2:I1436,"<="&DATE(2025,6,15),payment!A2:A1436,"=VARNISHED") -> 0 | G4: =SUMIFS(payment!H2:H1436,payment!I2:I1436,">="&DATE(2025,6,8),payment!I2:I1436,"<="&DATE(2025,6,15),payment!A2:A1436,"=NBE") -> 0 | H4: =SUMIFS(payment!H2:H1436,payment!I2:I1436,">="&DATE(2025,6,8),payment!I2:I1436,"<="&DATE(2025,6,15),payment!A2:A1436,"=PT") -> 0 | I4: =SUMIFS(payment!H2:H1436,payment!I2:I1436,">="&DATE(2025,6,8),payment!I2:I1436,"<="&DATE(2025,6,15),payment!A2:A1436,"=IN") -> 0 | J4: =SUMIFS(payment!H2:H1436,payment!I2:I1436,">="&DATE(2025,6,8),payment!I2:I1436,"<="&DATE(2025,6,15),payment!A2:A1436,"=NF") -> 0 | K4: =J4*7.1 -> 0 | L4: =SUMIFS(payment!H2:H1436,payment!L2:L1436,">="&DATE(2025,6,8),payment!L2:L1436,"<="&DATE(2025,6,15)) -> 0 | M4: =payment!AH$1-C4+L4 -> 3512729.1
B5: June 16-23 | C5: =SUMIFS(payment!H2:H1436,payment!I2:I1436,">="&DATE(2025,6,16),payment!I2:I1436,"<="&DATE(2025,6,23)) -> -0.0049999999 | E5: =SUMIFS(payment!H2:H1436,payment!I2:I1436,">="&DATE(2025,6,16),payment!I2:I1436,"<="&DATE(2025,6,23),payment!A2:A1436,"=TW") -> 0 | F5: =SUMIFS(payment!H2:H1436,payment!I2:I1436,">="&DATE(2025,6,16),payment!I2:I1436,"<="&DATE(2025,6,23),payment!A2:A1436,"=VARNISHED") -> 0 | G5: =SUMIFS(payment!H2:H1436,payment!I2:I1436,">="&DATE(2025,6,16),payment!I2:I1436,"<="&DATE(2025,6,23),payment!A2:A1436,"=NBE") -> 0 | H5: =SUMIFS(payment!H2:H1436,payment!I2:I1436,">="&DATE(2025,6,16),payment!I2:I1436,"<="&DATE(2025,6,23),payment!A2:A1436,"=PT") -> -0.0049999999 | I5: =SUMIFS(payment!H2:H1436,payment!I2:I1436,">="&DATE(2025,6,16),payment!I2:I1436,"<="&DATE(2025,6,23),payment!A2:A1436,"=IN") -> 0 | J5: =SUMIFS(payment!H2:H1436,payment!I2:I1436,">="&DATE(2025,6,16),payment!I2:I1436,"<="&DATE(2025,6,23),payment!A2:A1436,"=NF") -> 0 | K5: =J5*7.1 -> 0 | L5: =SUMIFS(payment!H2:H1436,payment!L2:L1436,">="&DATE(2025,6,16),payment!L2:L1436,"<="&DATE(2025,6,23)) -> 0 | M5: =M4-C5+L5 -> 3512729.1
B6: June 24-30 | C6: =SUMIFS(payment!H2:H1436,payment!I2:I1436,">="&DATE(2025,6,24),payment!I2:I1436,"<="&DATE(2025,6,30)) -> 0.004 | E6: =SUMIFS(payment!H2:H1436,payment!I2:I1436,">="&DATE(2025,6,24),payment!I2:I1436,"<="&DATE(2025,6,30),payment!A2:A1436,"=TW") -> 0 | F6: =SUMIFS(payment!H2:H1436,payment!I2:I1436,">="&DATE(2025,6,24),payment!I2:I1436,"<="&DATE(2025,6,30),payment!A2:A1436,"=VARNISHED") -> 0 | G6: =SUMIFS(payment!H2:H1436,payment!I2:I1436,">="&DATE(2025,6,24),payment!I2:I1436,"<="&DATE(2025,6,30),payment!A2:A1436,"=NBE") -> 0.004 | H6: =SUMIFS(payment!H2:H1436,payment!I2:I1436,">="&DATE(2025,6,24),payment!I2:I1436,"<="&DATE(2025,6,30),payment!A2:A1436,"=PT") -> 0 | I6: =SUMIFS(payment!H2:H1436,payment!I2:I1436,">="&DATE(2025,6,24),payment!I2:I1436,"<="&DATE(2025,6,30),payment!A2:A1436,"=IN") -> 0 | J6: =SUMIFS(payment!H2:H1436,payment!I2:I1436,">="&DATE(2025,6,24),payment!I2:I1436,"<="&DATE(2025,6,30),payment!A2:A1436,"=NF") -> 0 | K6: =J6*7.1 -> 0 | L6: =SUMIFS(payment!H2:H1436,payment!L2:L1436,">="&DATE(2025,6,24),payment!L2:L1436,"<="&DATE(2025,6,30)) -> 0 | M6: =M5-C6+L6 -> 3512729.1
B7: July 1-7 | C7: =SUMIFS(payment!H2:H1436,payment!I2:I1436,">="&DATE(2025,7,1),payment!I2:I1436,"<="&DATE(2025,7,7)) -> 0 | E7: =SUMIFS(payment!H2:H1436,payment!I2:I1436,">="&DATE(2025,7,1),payment!I2:I1436,"<="&DATE(2025,7,7),payment!A2:A1436,"=TW") -> 0 | F7: =SUMIFS(payment!H2:H1436,payment!I2:I1436,">="&DATE(2025,7,1),payment!I2:I1436,"<="&DATE(2025,7,7),payment!A2:A1436,"=VARNISHED") -> 0 | G7: =SUMIFS(payment!H2:H1436,payment!I2:I1436,">="&DATE(2025,7,1),payment!I2:I1436,"<="&DATE(2025,7,7),payment!A2:A1436,"=NBE") -> 0 | H7: =SUMIFS(payment!H2:H1436,payment!I2:I1436,">="&DATE(2025,7,1),payment!I2:I1436,"<="&DATE(2025,7,7),payment!A2:A1436,"=PT") -> 0 | I7: =SUMIFS(payment!H2:H1436,payment!I2:I1436,">="&DATE(2025,7,1),payment!I2:I1436,"<="&DATE(2025,7,7),payment!A2:A1436,"=IN") -> 0 | J7: =SUMIFS(payment!H2:H1436,payment!I2:I1436,">="&DATE(2025,7,1),payment!I2:I1436,"<="&DATE(2025,7,7),payment!A2:A1436,"=NF") -> 0 | K7: =J7*7.1 -> 0 | L7: =SUMIFS(payment!H2:H1453,payment!L2:L1453,">="&DATE(2025,7,1),payment!L2:L1453,"<="&DATE(2025,7,7)) -> 0 | M7: =M6-C7+L7 -> 3512729.1
B8: July 8-15 | C8: =SUMIFS(payment!H2:H1436,payment!I2:I1436,">="&DATE(2025,7,8),payment!I2:I1436,"<="&DATE(2025,7,15)) -> 0 | E8: =SUMIFS(payment!H2:H1436,payment!I2:I1436,">="&DATE(2025,7,8),payment!I2:I1436,"<="&DATE(2025,7,15),payment!A2:A1436,"=TW") -> 0 | F8: =SUMIFS(payment!H2:H1436,payment!I2:I1436,">="&DATE(2025,7,8),payment!I2:I1436,"<="&DATE(2025,7,15),payment!A2:A1436,"=VARNISHED") -> 0 | G8: =SUMIFS(payment!H2:H1436,payment!I2:I1436,">="&DATE(2025,7,8),payment!I2:I1436,"<="&DATE(2025,7,15),payment!A2:A1436,"=NBE") -> 0 | H8: =SUMIFS(payment!H2:H1436,payment!I2:I1436,">="&DATE(2025,7,8),payment!I2:I1436,"<="&DATE(2025,7,15),payment!A2:A1436,"=PT") -> 0 | I8: =SUMIFS(payment!H2:H1436,payment!I2:I1436,">="&DATE(2025,7,8),payment!I2:I1436,"<="&DATE(2025,7,15),payment!A2:A1436,"=IN") -> 0 | J8: =SUMIFS(payment!H2:H1436,payment!I2:I1436,">="&DATE(2025,7,8),payment!I2:I1436,"<="&DATE(2025,7,15),payment!A2:A1436,"=NF") -> 0 | K8: =J8*7.1 -> 0 | L8: =SUMIFS(payment!H2:H1453,payment!L2:L1453,">="&DATE(2025,7,8),payment!L2:L1453,"<="&DATE(2025,7,15)) -> 0 | M8: =M7-C8+L8 -> 3512729.1
B9: July 16-23 | C9: =SUMIFS(payment!H2:H1436,payment!I2:I1436,">="&DATE(2025,7,16),payment!I2:I1436,"<="&DATE(2025,7,23)) -> 0 | E9: =SUMIFS(payment!H2:H1436,payment!I2:I1436,">="&DATE(2025,7,16),payment!I2:I1436,"<="&DATE(2025,7,23),payment!A2:A1436,"=TW") -> 0 | F9: =SUMIFS(payment!H2:H1436,payment!I2:I1436,">="&DATE(2025,7,16),payment!I2:I1436,"<="&DATE(2025,7,23),payment!A2:A1436,"=VARNISHED") -> 0 | G9: =SUMIFS(payment!H2:H1436,payment!I2:I1436,">="&DATE(2025,7,16),payment!I2:I1436,"<="&DATE(2025,7,23),payment!A2:A1436,"=NBE") -> 0 | H9: =SUMIFS(payment!H2:H1436,payment!I2:I1436,">="&DATE(2025,7,16),payment!I2:I1436,"<="&DATE(2025,7,23),payment!A2:A1436,"=PT") -> 0 | I9: =SUMIFS(payment!H2:H1436,payment!I2:I1436,">="&DATE(2025,7,16),payment!I2:I1436,"<="&DATE(2025,7,23),payment!A2:A1436,"=IN") -> 0 | J9: =SUMIFS(payment!H2:H1436,payment!I2:I1436,">="&DATE(2025,7,16),payment!I2:I1436,"<="&DATE(2025,7,23),payment!A2:A1436,"=NF") -> 0 | K9: =J9*7.1 -> 0 | L9: =SUMIFS(payment!H2:H1453,payment!L2:L1453,">="&DATE(2025,7,16),payment!L2:L1453,"<="&DATE(2025,7,23)) -> 0.002 | M9: =M8-C9+L9 -> 3512729.1
B10: July 24-31 | C10: =SUMIFS(payment!H2:H1436,payment!I2:I1436,">="&DATE(2025,7,24),payment!I2:I1436,"<="&DATE(2025,7,31)) -> 0.0075 | E10: =SUMIFS(payment!H2:H1436,payment!I2:I1436,">="&DATE(2025,7,24),payment!I2:I1436,"<="&DATE(2025,7,31),payment!A2:A1436,"=TW") -> 0.0075 | F10: =SUMIFS(payment!H2:H1436,payment!I2:I1436,">="&DATE(2025,7,24),payment!I2:I1436,"<="&DATE(2025,7,31),payment!A2:A1436,"=VARNISHED") -> 0 | G10: =SUMIFS(payment!H2:H1436,payment!I2:I1436,">="&DATE(2025,7,24),payment!I2:I1436,"<="&DATE(2025,7,31),payment!A2:A1436,"=NBE") -> 0 | H10: =SUMIFS(payment!H2:H1436,payment!I2:I1436,">="&DATE(2025,7,24),payment!I2:I1436,"<="&DATE(2025,7,31),payment!A2:A1436,"=PT") -> 0 | I10: =SUMIFS(payment!H2:H1436,payment!I2:I1436,">="&DATE(2025,7,24),payment!I2:I1436,"<="&DATE(2025,7,31),payment!A2:A1436,"=IN") -> 0 | J10: =SUMIFS(payment!H2:H1436,payment!I2:I1436,">="&DATE(2025,7,24),payment!I2:I1436,"<="&DATE(2025,7,31),payment!A2:A1436,"=NF") -> 0 | K10: =J10*7.1 -> 0 | L10: =SUMIFS(payment!H2:H1453,payment!L2:L1453,">="&DATE(2025,7,24),payment!L2:L1453,"<="&DATE(2025,7,31)) -> 0 | M10: =M9-C10+L10 -> 3512729.1
B11: August 1-7 | C11: =SUMIFS(payment!H2:H1436,payment!I2:I1436,">="&DATE(2025,8,1),payment!I2:I1436,"<="&DATE(2025,8,7)) -> 0.00079999998 | E11: =SUMIFS(payment!H2:H1436,payment!I2:I1436,">="&DATE(2025,8,1),payment!I2:I1436,"<="&DATE(2025,8,7),payment!A2:A1436,"=TW") -> 0 | F11: =SUMIFS(payment!H2:H1436,payment!I2:I1436,">="&DATE(2025,8,1),payment!I2:I1436,"<="&DATE(2025,8,7),payment!A2:A1436,"=VARNISHED") -> 0 | G11: =SUMIFS(payment!H2:H1436,payment!I2:I1436,">="&DATE(2025,8,1),payment!I2:I1436,"<="&DATE(2025,8,7),payment!A2:A1436,"=NBE") -> 0 | H11: =SUMIFS(payment!H2:H1436,payment!I2:I1436,">="&DATE(2025,8,1),payment!I2:I1436,"<="&DATE(2025,8,7),payment!A2:A1436,"=PT") -> 0 | I11: =SUMIFS(payment!H2:H1436,payment!I2:I1436,">="&DATE(2025,8,1),payment!I2:I1436,"<="&DATE(2025,8,7),payment!A2:A1436,"=IN") -> 0.00079999998 | J11: =SUMIFS(payment!H2:H1436,payment!I2:I1436,">="&DATE(2025,8,1),payment!I2:I1436,"<="&DATE(2025,8,7),payment!A2:A1436,"=NF") -> 0 | K11: =J11*7.1 -> 0 | L11: =SUMIFS(payment!H2:H1453,payment!L2:L1453,">="&DATE(2025,8,1),payment!L2:L1453,"<="&DATE(2025,8,7)) -> 0 | M11: =M10-C11+L11 -> 3512729.1
B12: August 8-15 | C12: =SUMIFS(payment!H2:H1436,payment!I2:I1436,">="&DATE(2025,8,8),payment!I2:I1436,"<="&DATE(2025,8,15)) -> 0 | E12: =SUMIFS(payment!H2:H1436,payment!I2:I1436,">="&DATE(2025,8,8),payment!I2:I1436,"<="&DATE(2025,8,15),payment!A2:A1436,"=TW") -> 0 | F12: =SUMIFS(payment!H2:H1436,payment!I2:I1436,">="&DATE(2025,8,8),payment!I2:I1436,"<="&DATE(2025,8,15),payment!A2:A1436,"=VARNISHED") -> 0 | G12: =SUMIFS(payment!H2:H1436,payment!I2:I1436,">="&DATE(2025,8,8),payment!I2:I1436,"<="&DATE(2025,8,15),payment!A2:A1436,"=NBE") -> 0 | H12: =SUMIFS(payment!H2:H1436,payment!I2:I1436,">="&DATE(2025,8,8),payment!I2:I1436,"<="&DATE(2025,8,15),payment!A2:A1436,"=PT") -> 0 | I12: =SUMIFS(payment!H2:H1436,payment!I2:I1436,">="&DATE(2025,8,8),payment!I2:I1436,"<="&DATE(2025,8,15),payment!A2:A1436,"=IN") -> 0 | J12: =SUMIFS(payment!H2:H1436,payment!I2:I1436,">="&DATE(2025,8,8),payment!I2:I1436,"<="&DATE(2025,8,15),payment!A2:A1436,"=NF") -> 0 | K12: =J12*7.1 -> 0 | L12: =SUMIFS(payment!H2:H1453,payment!L2:L1453,">="&DATE(2025,8,8),payment!L2:L1453,"<="&DATE(2025,8,15)) -> 0 | M12: =M11-C12+L12 -> 3512729.1
B13: August 16-23 | C13: =SUMIFS(payment!H2:H1436,payment!I2:I1436,">="&DATE(2025,8,16),payment!I2:I1436,"<="&DATE(2025,8,23)) -> 0 | E13: =SUMIFS(payment!H2:H1436,payment!I2:I1436,">="&DATE(2025,8,16),payment!I2:I1436,"<="&DATE(2025,8,23),payment!A2:A1436,"=TW") -> 0 | F13: =SUMIFS(payment!H2:H1436,payment!I2:I1436,">="&DATE(2025,8,16),payment!I2:I1436,"<="&DATE(2025,8,23),payment!A2:A1436,"=VARNISHED") -> 0 | G13: =SUMIFS(payment!H2:H1436,payment!I2:I1436,">="&DATE(2025,8,16),payment!I2:I1436,"<="&DATE(2025,8,23),payment!A2:A1436,"=NBE") -> 0 | H13: =SUMIFS(payment!H2:H1436,payment!I2:I1436,">="&DATE(2025,8,16),payment!I2:I1436,"<="&DATE(2025,8,23),payment!A2:A1436,"=PT") -> 0 | I13: =SUMIFS(payment!H2:H1436,payment!I2:I1436,">="&DATE(2025,8,16),payment!I2:I1436,"<="&DATE(2025,8,23),payment!A2:A1436,"=IN") -> 0 | J13: =SUMIFS(payment!H2:H1436,payment!I2:I1436,">="&DATE(2025,8,16),payment!I2:I1436,"<="&DATE(2025,8,23),payment!A2:A1436,"=NF") -> 0 | K13: =J13*7.1 -> 0 | L13: =SUMIFS(payment!H2:H1453,payment!L2:L1453,">="&DATE(2025,8,16),payment!L2:L1453,"<="&DATE(2025,8,23)) -> 0 | M13: =M12-C13+L13 -> 3512729.1
B14: August 24-31 | C14: =SUMIFS(payment!H2:H1436,payment!I2:I1436,">="&DATE(2025,8,24),payment!I2:I1436,"<="&DATE(2025,8,31)) -> 0.004 | E14: =SUMIFS(payment!H2:H1436,payment!I2:I1436,">="&DATE(2025,8,24),payment!I2:I1436,"<="&DATE(2025,8,31),payment!A2:A1436,"=TW") -> 0.004 | F14: =SUMIFS(payment!H2:H1436,payment!I2:I1436,">="&DATE(2025,8,24),payment!I2:I1436,"<="&DATE(2025,8,31),payment!A2:A1436,"=VARNISHED") -> 0 | G14: =SUMIFS(payment!H2:H1436,payment!I2:I1436,">="&DATE(2025,8,24),payment!I2:I1436,"<="&DATE(2025,8,31),payment!A2:A1436,"=NBE") -> 0 | H14: =SUMIFS(payment!H2:H1436,payment!I2:I1436,">="&DATE(2025,8,24),payment!I2:I1436,"<="&DATE(2025,8,31),payment!A2:A1436,"=PT") -> 0 | I14: =SUMIFS(payment!H2:H1436,payment!I2:I1436,">="&DATE(2025,8,24),payment!I2:I1436,"<="&DATE(2025,8,31),payment!A2:A1436,"=IN") -> 0 | J14: =SUMIFS(payment!H2:H1436,payment!I2:I1436,">="&DATE(2025,8,24),payment!I2:I1436,"<="&DATE(2025,8,31),payment!A2:A1436,"=NF") -> 0 | K14: =J14*7.1 -> 0 | L14: =SUMIFS(payment!H2:H1453,payment!L2:L1453,">="&DATE(2025,8,24),payment!L2:L1453,"<="&DATE(2025,8,31)) -> 0 | M14: =M13-C14+L14 -> 3512729.1
B15: September 1-7 | C15: =SUMIFS(payment!H2:H1436,payment!I2:I1436,">="&DATE(2025,9,1),payment!I2:I1436,"<="&DATE(2025,9,7)) -> 0 | E15: =SUMIFS(payment!H2:H1436,payment!I2:I1436,">="&DATE(2025,9,1),payment!I2:I1436,"<="&DATE(2025,9,7),payment!A2:A1436,"=TW") -> 0 | F15: =SUMIFS(payment!H2:H1436,payment!I2:I1436,">="&DATE(2025,9,1),payment!I2:I1436,"<="&DATE(2025,9,7),payment!A2:A1436,"=VARNISHED") -> 0 | G15: =SUMIFS(payment!H2:H1436,payment!I2:I1436,">="&DATE(2025,9,1),payment!I2:I1436,"<="&DATE(2025,9,7),payment!A2:A1436,"=NBE") -> 0 | H15: =SUMIFS(payment!H2:H1436,payment!I2:I1436,">="&DATE(2025,9,1),payment!I2:I1436,"<="&DATE(2025,9,7),payment!A2:A1436,"=PT") -> 0 | I15: =SUMIFS(payment!H2:H1436,payment!I2:I1436,">="&DATE(2025,9,1),payment!I2:I1436,"<="&DATE(2025,9,7),payment!A2:A1436,"=IN") -> 0 | J15: =SUMIFS(payment!H2:H1436,payment!I2:I1436,">="&DATE(2025,9,1),payment!I2:I1436,"<="&DATE(2025,9,7),payment!A2:A1436,"=NF") -> 0 | K15: =J15*7.1 -> 0 | L15: =SUMIFS(payment!H2:H1453,payment!L2:L1453,">="&DATE(2025,9,1),payment!L2:L1453,"<="&DATE(2025,9,7)) -> 0 | M15: =M14-C15+L15 -> 3512729.1
B16: September 8-15 | C16: =SUMIFS(payment!H2:H1436,payment!I2:I1436,">="&DATE(2025,9,8),payment!I2:I1436,"<="&DATE(2025,9,15)) -> 0 | E16: =SUMIFS(payment!H2:H1436,payment!I2:I1436,">="&DATE(2025,9,8),payment!I2:I1436,"<="&DATE(2025,9,15),payment!A2:A1436,"=TW") -> 0 | F16: =SUMIFS(payment!H2:H1436,payment!I2:I1436,">="&DATE(2025,9,8),payment!I2:I1436,"<="&DATE(2025,9,15),payment!A2:A1436,"=VARNISHED") -> 0 | G16: =SUMIFS(payment!H2:H1436,payment!I2:I1436,">="&DATE(2025,9,8),payment!I2:I1436,"<="&DATE(2025,9,15),payment!A2:A1436,"=NBE") -> 0 | H16: =SUMIFS(payment!H2:H1436,payment!I2:I1436,">="&DATE(2025,9,8),payment!I2:I1436,"<="&DATE(2025,9,15),payment!A2:A1436,"=PT") -> 0 | I16: =SUMIFS(payment!H2:H1436,payment!I2:I1436,">="&DATE(2025,9,8),payment!I2:I1436,"<="&DATE(2025,9,15),payment!A2:A1436,"=IN") -> 0 | J16: =SUMIFS(payment!H2:H1436,payment!I2:I1436,">="&DATE(2025,9,8),payment!I2:I1436,"<="&DATE(2025,9,15),payment!A2:A1436,"=NF") -> 0 | K16: =J16*7.1 -> 0 | L16: =SUMIFS(payment!H2:H1453,payment!L2:L1453,">="&DATE(2025,9,8),payment!L2:L1453,"<="&DATE(2025,9,15)) -> 0 | M16: =M15-C16+L16 -> 3512729.1
B17: September 16-23 | C17: =SUMIFS(payment!H2:H1436,payment!I2:I1436,">="&DATE(2025,9,16),payment!I2:I1436,"<="&DATE(2025,9,23)) -> 0.0035 | E17: =SUMIFS(payment!H2:H1436,payment!I2:I1436,">="&DATE(2025,9,16),payment!I2:I1436,"<="&DATE(2025,9,23),payment!A2:A1436,"=TW") -> 0 | F17: =SUMIFS(payment!H2:H1436,payment!I2:I1436,">="&DATE(2025,9,16),payment!I2:I1436,"<="&DATE(2025,9,23),payment!A2:A1436,"=VARNISHED") -> 0 | G17: =SUMIFS(payment!H2:H1436,payment!I2:I1436,">="&DATE(2025,9,16),payment!I2:I1436,"<="&DATE(2025,9,23),payment!A2:A1436,"=NBE") -> 0 | H17: =SUMIFS(payment!H2:H1436,payment!I2:I1436,">="&DATE(2025,9,16),payment!I2:I1436,"<="&DATE(2025,9,23),payment!A2:A1436,"=PT") -> 0 | I17: =SUMIFS(payment!H2:H1436,payment!I2:I1436,">="&DATE(2025,9,16),payment!I2:I1436,"<="&DATE(2025,9,23),payment!A2:A1436,"=IN") -> 0.0035 | J17: =SUMIFS(payment!H2:H1436,payment!I2:I1436,">="&DATE(2025,9,16),payment!I2:I1436,"<="&DATE(2025,9,23),payment!A2:A1436,"=NF") -> 0 | K17: =J17*7.1 -> 0 | L17: =SUMIFS(payment!H2:H1453,payment!L2:L1453,">="&DATE(2025,9,16),payment!L2:L1453,"<="&DATE(2025,9,23)) -> 0 | M17: =M16-C17+L17 -> 3512729.1
B18: September 24-30 | C18: =SUMIFS(payment!H2:H1436,payment!I2:I1436,">="&DATE(2025,9,24),payment!I2:I1436,"<="&DATE(2025,9,30)) -> 0 | E18: =SUMIFS(payment!H2:H1436,payment!I2:I1436,">="&DATE(2025,9,24),payment!I2:I1436,"<="&DATE(2025,9,30),payment!A2:A1436,"=TW") -> 0 | F18: =SUMIFS(payment!H2:H1436,payment!I2:I1436,">="&DATE(2025,9,24),payment!I2:I1436,"<="&DATE(2025,9,30),payment!A2:A1436,"=VARNISHED") -> 0 | G18: =SUMIFS(payment!H2:H1436,payment!I2:I1436,">="&DATE(2025,9,24),payment!I2:I1436,"<="&DATE(2025,9,30),payment!A2:A1436,"=NBE") -> 0 | H18: =SUMIFS(payment!H2:H1436,payment!I2:I1436,">="&DATE(2025,9,24),payment!I2:I1436,"<="&DATE(2025,9,30),payment!A2:A1436,"=PT") -> 0 | I18: =SUMIFS(payment!H2:H1436,payment!I2:I1436,">="&DATE(2025,9,24),payment!I2:I1436,"<="&DATE(2025,9,30),payment!A2:A1436,"=IN") -> 0 | J18: =SUMIFS(payment!H2:H1436,payment!I2:I1436,">="&DATE(2025,9,24),payment!I2:I1436,"<="&DATE(2025,9,30),payment!A2:A1436,"=NF") -> 0 | K18: =J18*7.1 -> 0 | L18: =SUMIFS(payment!H2:H1453,payment!L2:L1453,">="&DATE(2025,9,24),payment!L2:L1453,"<="&DATE(2025,9,30)) -> 0 | M18: =M17-C18+L18 -> 3512729.1
B19: October 1-7 | C19: =SUMIFS(payment!H2:H1436,payment!I2:I1436,">="&DATE(2025,10,1),payment!I2:I1436,"<="&DATE(2025,10,7)) -> 0 | E19: =SUMIFS(payment!H2:H1436,payment!I2:I1436,">="&DATE(2025,10,1),payment!I2:I1436,"<="&DATE(2025,10,7),payment!A2:A1436,"=TW") -> 0 | F19: =SUMIFS(payment!H2:H1436,payment!I2:I1436,">="&DATE(2025,10,1),payment!I2:I1436,"<="&DATE(2025,10,7),payment!A2:A1436,"=VARNISHED") -> 0 | G19: =SUMIFS(payment!H2:H1436,payment!I2:I1436,">="&DATE(2025,10,1),payment!I2:I1436,"<="&DATE(2025,10,7),payment!A2:A1436,"=NBE") -> 0 | H19: =SUMIFS(payment!H2:H1436,payment!I2:I1436,">="&DATE(2025,10,1),payment!I2:I1436,"<="&DATE(2025,10,7),payment!A2:A1436,"=PT") -> 0 | I19: =SUMIFS(payment!H2:H1436,payment!I2:I1436,">="&DATE(2025,10,1),payment!I2:I1436,"<="&DATE(2025,10,7),payment!A2:A1436,"=IN") -> 0 | J19: =SUMIFS(payment!H2:H1436,payment!I2:I1436,">="&DATE(2025,10,1),payment!I2:I1436,"<="&DATE(2025,10,7),payment!A2:A1436,"=NF") -> 0 | K19: =J19*7.1 -> 0 | L19: =SUMIFS(payment!H2:H1453,payment!L2:L1453,">="&DATE(2025,10,1),payment!L2:L1453,"<="&DATE(2025,10,7)) -> 0 | M19: =M18-C19+L19 -> 3512729.1
B20: October 8-15 | C20: =SUMIFS(payment!H2:H1436,payment!I2:I1436,">="&DATE(2025,10,8),payment!I2:I1436,"<="&DATE(2025,10,15)) -> -0.00212 | E20: =SUMIFS(payment!H2:H1436,payment!I2:I1436,">="&DATE(2025,10,8),payment!I2:I1436,"<="&DATE(2025,10,15),payment!A2:A1436,"=TW") -> 0 | F20: =SUMIFS(payment!H2:H1436,payment!I2:I1436,">="&DATE(2025,10,8),payment!I2:I1436,"<="&DATE(2025,10,15),payment!A2:A1436,"=VARNISHED") -> 0 | G20: =SUMIFS(payment!H2:H1436,payment!I2:I1436,">="&DATE(2025,10,8),payment!I2:I1436,"<="&DATE(2025,10,15),payment!A2:A1436,"=NBE") -> 0 | H20: =SUMIFS(payment!H2:H1436,payment!I2:I1436,">="&DATE(2025,10,8),payment!I2:I1436,"<="&DATE(2025,10,15),payment!A2:A1436,"=PT") -> -0.00212 | I20: =SUMIFS(payment!H2:H1436,payment!I2:I1436,">="&DATE(2025,10,8),payment!I2:I1436,"<="&DATE(2025,10,15),payment!A2:A1436,"=IN") -> 0 | J20: =SUMIFS(payment!H2:H1436,payment!I2:I1436,">="&DATE(2025,10,8),payment!I2:I1436,"<="&DATE(2025,10,15),payment!A2:A1436,"=NF") -> 0 | K20: =J20*7.1 -> 0 | L20: =SUMIFS(payment!H2:H1453,payment!L2:L1453,">="&DATE(2025,10,8),payment!L2:L1453,"<="&DATE(2025,10,15)) -> 0 | M20: =M19-C20+L20 -> 3512729.1
B21: October 16-23 | C21: =SUMIFS(payment!H2:H1436,payment!I2:I1436,">="&DATE(2025,10,16),payment!I2:I1436,"<="&DATE(2025,10,23)) -> 0 | E21: =SUMIFS(payment!H2:H1436,payment!I2:I1436,">="&DATE(2025,10,16),payment!I2:I1436,"<="&DATE(2025,10,23),payment!A2:A1436,"=TW") -> 0 | F21: =SUMIFS(payment!H2:H1436,payment!I2:I1436,">="&DATE(2025,10,16),payment!I2:I1436,"<="&DATE(2025,10,23),payment!A2:A1436,"=VARNISHED") -> 0 | G21: =SUMIFS(payment!H2:H1436,payment!I2:I1436,">="&DATE(2025,10,16),payment!I2:I1436,"<="&DATE(2025,10,23),payment!A2:A1436,"=NBE") -> 0 | H21: =SUMIFS(payment!H2:H1436,payment!I2:I1436,">="&DATE(2025,10,16),payment!I2:I1436,"<="&DATE(2025,10,23),payment!A2:A1436,"=PT") -> 0 | I21: =SUMIFS(payment!H2:H1436,payment!I2:I1436,">="&DATE(2025,10,16),payment!I2:I1436,"<="&DATE(2025,10,23),payment!A2:A1436,"=IN") -> 0 | J21: =SUMIFS(payment!H2:H1436,payment!I2:I1436,">="&DATE(2025,10,16),payment!I2:I1436,"<="&DATE(2025,10,23),payment!A2:A1436,"=NF") -> 0 | K21: =J21*7.1 -> 0 | L21: =SUMIFS(payment!H2:H1453,payment!L2:L1453,">="&DATE(2025,10,16),payment!L2:L1453,"<="&DATE(2025,10,23)) -> 0 | M21: =M20-C21+L21 -> 3512729.1
B22: October 24-31 | C22: =SUMIFS(payment!H2:H1436,payment!I2:I1436,">="&DATE(2025,10,24),payment!I2:I1436,"<="&DATE(2025,10,31)) -> 3580 | E22: =SUMIFS(payment!H2:H1436,payment!I2:I1436,">="&DATE(2025,10,24),payment!I2:I1436,"<="&DATE(2025,10,31),payment!A2:A1436,"=TW") -> 0 | F22: =SUMIFS(payment!H2:H1436,payment!I2:I1436,">="&DATE(2025,10,24),payment!I2:I1436,"<="&DATE(2025,10,31),payment!A2:A1436,"=VARNISHED") -> 0 | G22: =SUMIFS(payment!H2:H1436,payment!I2:I1436,">="&DATE(2025,10,24),payment!I2:I1436,"<="&DATE(2025,10,31),payment!A2:A1436,"=NBE") -> 0 | H22: =SUMIFS(payment!H2:H1436,payment!I2:I1436,">="&DATE(2025,10,24),payment!I2:I1436,"<="&DATE(2025,10,31),payment!A2:A1436,"=PT") -> 0 | I22: =SUMIFS(payment!H2:H1436,payment!I2:I1436,">="&DATE(2025,10,24),payment!I2:I1436,"<="&DATE(2025,10,31),payment!A2:A1436,"=IN") -> 3580 | J22: =SUMIFS(payment!H2:H1436,payment!I2:I1436,">="&DATE(2025,10,24),payment!I2:I1436,"<="&DATE(2025,10,31),payment!A2:A1436,"=NF") -> 0 | K22: =J22*7.1 -> 0 | L22: =SUMIFS(payment!H2:H1453,payment!L2:L1453,">="&DATE(2025,10,24),payment!L2:L1453,"<="&DATE(2025,10,31)) -> 0 | M22: =M21-C22+L22 -> 3509149.1
B23: November 1-7 | C23: =SUMIFS(payment!H2:H1436,payment!I2:I1436,">="&DATE(2025,11,1),payment!I2:I1436,"<="&DATE(2025,11,7)) -> -0.0054 | E23: =SUMIFS(payment!H2:H1436,payment!I2:I1436,">="&DATE(2025,11,1),payment!I2:I1436,"<="&DATE(2025,11,7),payment!A2:A1436,"=TW") -> 0 | F23: =SUMIFS(payment!H2:H1436,payment!I2:I1436,">="&DATE(2025,11,1),payment!I2:I1436,"<="&DATE(2025,11,7),payment!A2:A1436,"=VARNISHED") -> 0.00099999999 | G23: =SUMIFS(payment!H2:H1436,payment!I2:I1436,">="&DATE(2025,11,1),payment!I2:I1436,"<="&DATE(2025,11,7),payment!A2:A1436,"=NBE") -> -0.004 | H23: =SUMIFS(payment!H2:H1436,payment!I2:I1436,">="&DATE(2025,11,1),payment!I2:I1436,"<="&DATE(2025,11,7),payment!A2:A1436,"=PT") -> 0 | I23: =SUMIFS(payment!H2:H1436,payment!I2:I1436,">="&DATE(2025,11,1),payment!I2:I1436,"<="&DATE(2025,11,7),payment!A2:A1436,"=IN") -> -0.0024 | J23: =SUMIFS(payment!H2:H1436,payment!I2:I1436,">="&DATE(2025,11,1),payment!I2:I1436,"<="&DATE(2025,11,7),payment!A2:A1436,"=NF") -> 0 | K23: =J23*7.1 -> 0 | L23: =SUMIFS(payment!H2:H1453,payment!L2:L1453,">="&DATE(2025,11,1),payment!L2:L1453,"<="&DATE(2025,11,7)) -> 0 | M23: =M22-C23+L23 -> 3509149.1
B24: November 8-15 | C24: =SUMIFS(payment!H2:H1436,payment!I2:I1436,">="&DATE(2025,11,8),payment!I2:I1436,"<="&DATE(2025,11,15)) -> 0 | E24: =SUMIFS(payment!H2:H1436,payment!I2:I1436,">="&DATE(2025,11,8),payment!I2:I1436,"<="&DATE(2025,11,15),payment!A2:A1436,"=TW") -> 0 | F24: =SUMIFS(payment!H2:H1436,payment!I2:I1436,">="&DATE(2025,11,8),payment!I2:I1436,"<="&DATE(2025,11,15),payment!A2:A1436,"=VARNISHED") -> 0 | G24: =SUMIFS(payment!H2:H1436,payment!I2:I1436,">="&DATE(2025,11,8),payment!I2:I1436,"<="&DATE(2025,11,15),payment!A2:A1436,"=NBE") -> 0 | H24: =SUMIFS(payment!H2:H1436,payment!I2:I1436,">="&DATE(2025,11,8),payment!I2:I1436,"<="&DATE(2025,11,15),payment!A2:A1436,"=PT") -> 0 | I24: =SUMIFS(payment!H2:H1436,payment!I2:I1436,">="&DATE(2025,11,8),payment!I2:I1436,"<="&DATE(2025,11,15),payment!A2:A1436,"=IN") -> 0 | J24: =SUMIFS(payment!H2:H1436,payment!I2:I1436,">="&DATE(2025,11,8),payment!I2:I1436,"<="&DATE(2025,11,15),payment!A2:A1436,"=NF") -> 0 | K24: =J24*7.1 -> 0 | L24: =SUMIFS(payment!H2:H1453,payment!L2:L1453,">="&DATE(2025,11,8),payment!L2:L1453,"<="&DATE(2025,11,15)) -> 0 | M24: =M23-C24+L24 -> 3509149.1
B25: November 16-23 | C25: =SUMIFS(payment!H2:H1436,payment!I2:I1436,">="&DATE(2025,11,16),payment!I2:I1436,"<="&DATE(2025,11,23)) -> 0 | E25: =SUMIFS(payment!H2:H1436,payment!I2:I1436,">="&DATE(2025,11,16),payment!I2:I1436,"<="&DATE(2025,11,23),payment!A2:A1436,"=TW") -> 0 | F25: =SUMIFS(payment!H2:H1436,payment!I2:I1436,">="&DATE(2025,11,16),payment!I2:I1436,"<="&DATE(2025,11,23),payment!A2:A1436,"=VARNISHED") -> 0 | G25: =SUMIFS(payment!H2:H1436,payment!I2:I1436,">="&DATE(2025,11,16),payment!I2:I1436,"<="&DATE(2025,11,23),payment!A2:A1436,"=NBE") -> 0 | H25: =SUMIFS(payment!H2:H1436,payment!I2:I1436,">="&DATE(2025,11,16),payment!I2:I1436,"<="&DATE(2025,11,23),payment!A2:A1436,"=PT") -> 0 | I25: =SUMIFS(payment!H2:H1436,payment!I2:I1436,">="&DATE(2025,11,16),payment!I2:I1436,"<="&DATE(2025,11,23),payment!A2:A1436,"=IN") -> 0 | J25: =SUMIFS(payment!H2:H1436,payment!I2:I1436,">="&DATE(2025,11,16),payment!I2:I1436,"<="&DATE(2025,11,23),payment!A2:A1436,"=NF") -> 0 | K25: =J25*7.1 -> 0 | L25: =SUMIFS(payment!H2:H1453,payment!L2:L1453,">="&DATE(2025,11,16),payment!L2:L1453,"<="&DATE(2025,11,23)) -> 0 | M25: =M24-C25+L25 -> 3509149.1
